2025-05-01 06:57:56.735025: I external/local_xla/xla/tsl/cuda/cudart_stub.cc:32] Could not find cuda drivers on your machine, GPU will not be used.
2025-05-01 06:57:56.738104: I external/local_xla/xla/tsl/cuda/cudart_stub.cc:32] Could not find cuda drivers on your machine, GPU will not be used.
2025-05-01 06:57:56.746580: E external/local_xla/xla/stream_executor/cuda/cuda_fft.cc:467] Unable to register cuFFT factory: Attempting to register factory for plugin cuFFT when one has already been registered
WARNING: All log messages before absl::InitializeLog() is called are written to STDERR
E0000 00:00:1746082676.760778    2065 cuda_dnn.cc:8579] Unable to register cuDNN factory: Attempting to register factory for plugin cuDNN when one has already been registered
E0000 00:00:1746082676.765005    2065 cuda_blas.cc:1407] Unable to register cuBLAS factory: Attempting to register factory for plugin cuBLAS when one has already been registered
W0000 00:00:1746082676.776572    2065 computation_placer.cc:177] computation placer already registered. Please check linkage and avoid linking the same target more than once.
W0000 00:00:1746082676.776596    2065 computation_placer.cc:177] computation placer already registered. Please check linkage and avoid linking the same target more than once.
W0000 00:00:1746082676.776599    2065 computation_placer.cc:177] computation placer already registered. Please check linkage and avoid linking the same target more than once.
W0000 00:00:1746082676.776601    2065 computation_placer.cc:177] computation placer already registered. Please check linkage and avoid linking the same target more than once.
2025-05-01 06:57:56.780097: I tensorflow/core/platform/cpu_feature_guard.cc:210] This TensorFlow binary is optimized to use available CPU instructions in performance-critical operations.
To enable the following instructions: AVX2 FMA, in other operations, rebuild TensorFlow with the appropriate compiler flags.
Traceback (most recent call last):
  File "/opt/hostedtoolcache/Python/3.10.17/x64/lib/python3.10/site-packages/pandas/core/indexes/datetimes.py", line 603, in get_loc
    parsed, reso = self._parse_with_reso(key)
  File "/opt/hostedtoolcache/Python/3.10.17/x64/lib/python3.10/site-packages/pandas/core/indexes/datetimes.py", line 559, in _parse_with_reso
    parsed, reso = super()._parse_with_reso(label)
  File "/opt/hostedtoolcache/Python/3.10.17/x64/lib/python3.10/site-packages/pandas/core/indexes/datetimelike.py", line 293, in _parse_with_reso
    parsed, reso_str = parsing.parse_datetime_string_with_reso(label, freqstr)
  File "parsing.pyx", line 442, in pandas._libs.tslibs.parsing.parse_datetime_string_with_reso
  File "parsing.pyx", line 666, in pandas._libs.tslibs.parsing.dateutil_parse
pandas._libs.tslibs.parsing.DateParseError: Unknown datetime string format, unable to parse: high

The above exception was the direct cause of the following exception:

Traceback (most recent call last):
  File "/home/runner/work/arkana/arkana/main.py", line 1003, in <module>
    results = list(executor.map(analyze_stock, STOCK_LIST))
  File "/opt/hostedtoolcache/Python/3.10.17/x64/lib/python3.10/concurrent/futures/_base.py", line 621, in result_iterator
    yield _result_or_cancel(fs.pop())
  File "/opt/hostedtoolcache/Python/3.10.17/x64/lib/python3.10/concurrent/futures/_base.py", line 319, in _result_or_cancel
    return fut.result(timeout)
  File "/opt/hostedtoolcache/Python/3.10.17/x64/lib/python3.10/concurrent/futures/_base.py", line 458, in result
    return self.__get_result()
  File "/opt/hostedtoolcache/Python/3.10.17/x64/lib/python3.10/concurrent/futures/_base.py", line 403, in __get_result
    raise self._exception
  File "/opt/hostedtoolcache/Python/3.10.17/x64/lib/python3.10/concurrent/futures/thread.py", line 58, in run
    result = self.fn(*self.args, **self.kwargs)
  File "/home/runner/work/arkana/arkana/main.py", line 493, in analyze_stock
    df = calculate_indicators(df)
  File "/home/runner/work/arkana/arkana/main.py", line 145, in calculate_indicators
    df['atr'] = ta.volatility.AverageTrueRange(high=df['high'], low=df['low'], close=df['close'], window=14).average_true_range()
  File "/opt/hostedtoolcache/Python/3.10.17/x64/lib/python3.10/site-packages/pandas/core/series.py", line 1121, in __getitem__
    return self._get_value(key)
  File "/opt/hostedtoolcache/Python/3.10.17/x64/lib/python3.10/site-packages/pandas/core/series.py", line 1237, in _get_value
    loc = self.index.get_loc(label)
  File "/opt/hostedtoolcache/Python/3.10.17/x64/lib/python3.10/site-packages/pandas/core/indexes/datetimes.py", line 605, in get_loc
    raise KeyError(key) from err
KeyError: 'high'
