2025-04-30 16:54:18.448756: I external/local_xla/xla/tsl/cuda/cudart_stub.cc:32] Could not find cuda drivers on your machine, GPU will not be used.
2025-04-30 16:54:18.451890: I external/local_xla/xla/tsl/cuda/cudart_stub.cc:32] Could not find cuda drivers on your machine, GPU will not be used.
2025-04-30 16:54:18.460347: E external/local_xla/xla/stream_executor/cuda/cuda_fft.cc:467] Unable to register cuFFT factory: Attempting to register factory for plugin cuFFT when one has already been registered
WARNING: All log messages before absl::InitializeLog() is called are written to STDERR
E0000 00:00:1746032058.474447    2065 cuda_dnn.cc:8579] Unable to register cuDNN factory: Attempting to register factory for plugin cuDNN when one has already been registered
E0000 00:00:1746032058.478658    2065 cuda_blas.cc:1407] Unable to register cuBLAS factory: Attempting to register factory for plugin cuBLAS when one has already been registered
W0000 00:00:1746032058.490291    2065 computation_placer.cc:177] computation placer already registered. Please check linkage and avoid linking the same target more than once.
W0000 00:00:1746032058.490315    2065 computation_placer.cc:177] computation placer already registered. Please check linkage and avoid linking the same target more than once.
W0000 00:00:1746032058.490318    2065 computation_placer.cc:177] computation placer already registered. Please check linkage and avoid linking the same target more than once.
W0000 00:00:1746032058.490320    2065 computation_placer.cc:177] computation placer already registered. Please check linkage and avoid linking the same target more than once.
2025-04-30 16:54:18.493944: I tensorflow/core/platform/cpu_feature_guard.cc:210] This TensorFlow binary is optimized to use available CPU instructions in performance-critical operations.
To enable the following instructions: AVX2 FMA, in other operations, rebuild TensorFlow with the appropriate compiler flags.
Tidak ada model yang ditemukan untuk dihapus.
Traceback (most recent call last):
  File "/opt/hostedtoolcache/Python/3.10.17/x64/lib/python3.10/site-packages/pandas/core/indexes/base.py", line 3805, in get_loc
    return self._engine.get_loc(casted_key)
  File "index.pyx", line 167, in pandas._libs.index.IndexEngine.get_loc
  File "index.pyx", line 196, in pandas._libs.index.IndexEngine.get_loc
  File "pandas/_libs/hashtable_class_helper.pxi", line 7081, in pandas._libs.hashtable.PyObjectHashTable.get_item
  File "pandas/_libs/hashtable_class_helper.pxi", line 7089, in pandas._libs.hashtable.PyObjectHashTable.get_item
KeyError: 'high'

The above exception was the direct cause of the following exception:

Traceback (most recent call last):
  File "/home/runner/work/arkana/arkana/main.py", line 757, in <module>
    results = list(executor.map(analyze_stock, STOCK_LIST))
  File "/opt/hostedtoolcache/Python/3.10.17/x64/lib/python3.10/concurrent/futures/_base.py", line 621, in result_iterator
    yield _result_or_cancel(fs.pop())
  File "/opt/hostedtoolcache/Python/3.10.17/x64/lib/python3.10/concurrent/futures/_base.py", line 319, in _result_or_cancel
    return fut.result(timeout)
  File "/opt/hostedtoolcache/Python/3.10.17/x64/lib/python3.10/concurrent/futures/_base.py", line 458, in result
    return self.__get_result()
  File "/opt/hostedtoolcache/Python/3.10.17/x64/lib/python3.10/concurrent/futures/_base.py", line 403, in __get_result
    raise self._exception
  File "/opt/hostedtoolcache/Python/3.10.17/x64/lib/python3.10/concurrent/futures/thread.py", line 58, in run
    result = self.fn(*self.args, **self.kwargs)
  File "/home/runner/work/arkana/arkana/main.py", line 344, in analyze_stock
    df = calculate_indicators(df)
  File "/home/runner/work/arkana/arkana/main.py", line 101, in calculate_indicators
    df = ta.trend.adx(df['high'], df['low'], df['close'], window=14, fillna=True)
  File "/opt/hostedtoolcache/Python/3.10.17/x64/lib/python3.10/site-packages/pandas/core/frame.py", line 4102, in __getitem__
    indexer = self.columns.get_loc(key)
  File "/opt/hostedtoolcache/Python/3.10.17/x64/lib/python3.10/site-packages/pandas/core/indexes/base.py", line 3812, in get_loc
    raise KeyError(key) from err
KeyError: 'high'
